Workbook

Sheet Analysis
A3: Row Labels | B3: Average of AVE Departure | E3: Row Labels | F3: Average of AVE Departure | H3: Row Labels | I3: Average of AVE Departure | J3: Tar
A4: January | B4: 44.994912 | E4: January | F4: 44.994912 | H4: October | I4: 46.609851 | J4: 45
A5: September | B5: 44.480208 | E5: September | F5: 44.480208 | H5: November | I5: 48.502326 | J5: 45
A6: October | B6: 46.609851 | E6: October | F6: 46.609851 | H6: December | I6: 47.503878 | J6: 45
A7: November | B7: 48.502326 | E7: November | F7: 48.502326 | H7: January | I7: 44.994912 | J7: 45
A8: December | B8: 47.503878 | E8: December | F8: 47.503878 | H8: Quarter | I8: =AVERAGE(I4:I7) -> 46.902742 | J8: 45
A9: (blank) | E9: (blank)
A10: Grand Total | B10: 46.929042 | E10: Grand Total | F10: 46.929042
E22: Row Labels | F22: October | G22: November | H22: December | I22: January
E23: Damaged stock replacement | F23: 58.733333 | G23: 59.225 | H23: 59.388889 | I23: 46.016667
E24: Delayed Check ins | F24: 54.336111 | G24: 57.763333 | H24: 55.52619 | I24: 50.769048
E25: Delayed order capture | F25: 47.105882 | G25: 47.673188 | H25: 47.701515 | I25: 51.809722
E26: DJ failures | F26: 57.527451 | G26: 51.883333 | H26: 52.757407 | I26: 54.12619
E27: Driver delays | F27: 56.645238 | G27: 56.05 | H27: 55.528571 | I27: 51.522917
E28: Late coming | F28: 60.044444 | G28: 54.714815 | H28: 58.246667 | I28: 50.175
E29: Pre-Trip inspection defect closure | F29: 63.516667 | G29: 70.853086 | H29: 59.505882 | I29: 58.347619
E30: Prolonged meeting. | G30: 60.044444 | H30: 59.225
E31: Reconcile stock count delays | F31: 58.25 | G31: 59.80303 | H31: 57.9 | I31: 54.426667
E32: Traffic at the exit gate. | G32: 59.154762 | H32: 59.448485
E33: unplanned trainings | F33: 54.046667 | G33: 55.805556 | H33: 55.809524 | I33: 51.885714
E34: Weigh bridge delays | F34: 59.225 | G34: 59.323333 | H34: 59.022549 | I34: 55.8
E35: Grand Total | F35: =AVERAGE(F23:F34) -> 56.943079 | G35: =AVERAGE(G23:G34) -> 57.691157 | H35: =AVERAGE(H23:H34) -> 56.671723 | I35: =AVERAGE(I23:I34) -> 52.487954

Sheet LIST 2
A1: CUSTOMER NAME | B1: KM 1 WAY | C1: KM 2 WAY | D1: DAYS IN TRADE | E1: POC TIME
A2: Kabaco U Ltd-Mbarara Tax No.: 1000025425 | B2: 10 | C2: =B2*2 -> 20 | D2: 1 | E2: 3
A3: Kabaco U Ltd Tax No.: 1000025425 | B3: 152 | C3: =B3*2 -> 304 | D3: 2 | E3: 3
A4: KATO INVESTMENTS LTD- KALISIZO Tax No.: 1000098824 | B4: 144 | C4: =B4*2 -> 288 | D4: 2 | E4: 3
A5: KATO INVESTMENTS LIMITED-MASAK Tax No.: 1000098824 | B5: 298 | C5: =B5*2 -> 596 | D5: 2 | E5: 3
A6: RUGOMA TRADERS CO. LTD NTUNGAM Tax No.: 1000249350 | B6: 75 | C6: =B6*2 -> 150 | D6: 1 | E6: 3
A7: Rugoma Traders-Kanungu/Kihihi Tax No.: 1000249350 | B7: 136 | C7: =B7*2 -> 272 | D7: 2 | E7: 3
A8: Boniface Harera Tax No.: 1000317747 | B8: 224 | C8: =B8*2 -> 448 | D8: 2 | E8: 3
A9: Bates Enterprises Ltd-Ntoroko Tax No.: 1001193253 | B9: 255 | C9: =B9*2 -> 510 | D9: 3 | E9: 3
A10: Sawan Distributors Ltd-Nabingo Tax No.: 1000186379 | B10: 280 | C10: =B10*2 -> 560 | D10: 2 | E10: 3
A11: Rugoma Traders-Rukungiri Tax No.: 1000249350 | B11: 128 | C11: =B11*2 -> 256 | D11: 2 | E11: 3
A12: Kobusinge Acaali- Kyenjojo Tax No.: 1000977837 | B12: 290 | C12: =B12*2 -> 580 | D12: 2 | E12: 3
A13: Kato Investments Ltd- Kakumiro Tax No.: 1000098824 | B13: 395 | C13: =B13*2 -> 790 | D13: 3 | E13: 3
... A28: Kachain Logistics Ltd Tax No.: 1005388662 | B28: 280 | C28: =B28*2 -> 560 | D28: 3 | E28: 3

Sheet Sheet2
N1: Month Name | O1: (All) | Q1: Row Labels | R1: Average of Total Hour Route
D2: Month Name | E2: (All) | G2: Average of AVE Departure | H2: Column Labels | Q2: January | R2: 40.935924
G3: Row Labels | H3: January | I3: February | J3: March | K3: April | L3: Grand Total | N3: Row Labels | O3: Count of Comment AVE Departure | Q3: February | R3: 42.306507
A4: Row Labels | B4: Average of AVE Departure | C4: TAR | D4: Row Labels | E4: Average of AVE Departure | G4: Mbogo bashil | J4: 23.888889 | L4: 23.888889 | N4: DJ failures | O4: 20 | Q4: March | R4: 41.509128 | W4: Row Labels | X4: Average of AVE Arrival Time
A5: January | B5: 43.986135 | C5: 45 | D5: Mbogo bashil | E5: 23.888889 | G5: Awali Malinzi | J5: 26.078704 | L5: 26.078704 | N5: Jam at the weigh bridge | O5: 12 | Q5: April | R5: 39.488205 | W5: January | X5: 55.873067
A6: February | B6: 42.703066 | C6: 45 | D6: Muzamiru | E6: 25.87963 | G6: Kyapa Hakim | J6: 26.875 | L6: 26.875 | N6: Pre-Trip inspection defect closure | O6: 10 | Q6: Grand Total | R6: 41.420317 | W6: February | X6: 55.160639
A7: March | B7: 30.284293 | C7: 45 | D7: Awali Malinzi | E7: 26.078704 | G7: kakembo Masudi | I7: 42.966821 | J7: 26.21142 | L7: 32.91358 | N7: Unplanned Training | O7: 3 | W7: March | X7: 50.415357
A8: April | B8: 32.349537 | D8: Kyapa Hakim | E8: 26.875 | G8: Malinzi Awali | I8: 43.298611 | J8: 27.87037 | L8: 33.013117 | N8: Reconciling stock count delays | O8: 3 | W8: April | X8: 43.158654
A9: Grand Total | B9: 37.530567 | D9: kakembo Masudi | E9: 32.91358 | G9: Ikwalikwa Yusuf | I9: 42.137346 | J9: 26.626157 | L9: 33.27381 | N9: Meeting Delays | O9: 2 | W9: Grand Total | X9: 52.195184
D10: Malinzi Awali | E10: 33.013117 | G10: Faruk Abel | I10: 42.089947 | J10: 28.423354 | L10: 34.402488 | N10: Driver delays | O10: 1
A11: Month | B11: AVE departure | C11: Tar | D11: Ikwalikwa Yusuf | E11: 33.27381 | G11: Stephen Musoke | H11: 41.407407 | I11: 42.65873 | J11: 27.273148 | K11: 26.54321 | L11: 34.837963 | N11: Damaged stock replacement | O11: 1
A12: January | B12: 43.986135 | C12: 45 | D12: Faruk Abel | E12: 34.402488 | G12: Kabene John | H12: 41.30787 | I12: 41.916152 | J12: 33.842593 | K12: 27.779882 | L12: 35.122354 | N12: Grand Total | O12: 52
A13: February | B13: 42.879726 | C13: 45 | D13: Stephen Musoke | E13: 34.837963 | G13: Bisaso Ronald | H13: 43.049769 | I13: 41.606481 | J13: 26.875 | K13: 27.87037 | L13: 35.423475
A14: March | B14: 42.669737 | C14: 45 | D14: Kabene John | E14: 35.122354 | G14: Abel Mark naffa | H14: 39.814815 | I14: 42.137346 | J14: 27.87037 | K14: 31.851852 | L14: 35.594444
A15: quarter | B15: =AVERAGE(B12:B14) -> 43.178533 | C15: =AVERAGE(C12:C14) -> 45 | D15: Bisaso Ronald | E15: 35.423475 | G15: Lule Fred | I15: 42.552083 | J15: 27.20679 | L15: 35.975529
D16: Abel Mark naffa | E16: 35.594444 | G16: Nassasira | J16: 36.165123 | L16: 36.165123
D17: Lule Fred | E17: 35.975529 | G17: Nminya Siraje | I17: 41.681134 | J17: 29.861111 | L17: 36.165123
D18: Nassasira | E18: 36.165123 | G18: Mulumba Kasim | I18: 42.502315 | J18: 27.159392 | L18: 36.184641
D19: Nminya Siraje | E19: 36.165123 | G19: Byanshala Stoney | I19: 42.026749 | J19: 29.985532 | L19: 36.360294
D20: Mulumba Kasim | E20: 36.184641 | G20: Mudunga Musa | I20: 42.303241 | J20: 27.621528 | L20: 36.430556
D21: Byanshala Stoney | E21: 36.360294 | G21: kayanja Sam | I21: 42.943122 | J21: 30.145503 | L21: 36.544312 | N21: Row Labels
D22: Mudunga Musa | E22: 36.430556 | G22: (blank) | H22: 44.328305 | I22: 43.154544 | J22: 28.831418 | L22: 36.780926 | N22: Damaged stock replacement
D23: kayanja Sam | E23: 36.544312 | G23: MUKOSE MUZAMIRU | H23: 40.699588 | I23: 42.203704 | K23: 26.709105 | L23: 36.878472 | N23: Delayed Check ins
D24: MUKOSE MUZAMIRU | E24: 36.878472 | G24: Kilabila Ismail | H24: 44.69213 | I24: 42.00463 | J24: 39.31713 | K24: 28.451003 | L24: 37.137612 | N24: Delayed order capture
D25: Kilabila Ismail | E25: 37.137612 | G25: Nakalya John | H25: 56.736111 | I25: 41.031379 | J25: 30.607639 | L25: 37.271091 | N25: DJ failures
D26: GODWIN NIWENSIIMA | E26: 37.160494 | G26: Matovu Musa | I26: 42.303241 | J26: 27.372685 | L26: 37.326389 | N26: Driver delays
D27: Nakalya John | E27: 37.271091 | G27: Bwanga Gilbert | I27: 41.929977 | J27: 31.685957 | L27: 37.539683 | N27: Late coming
D28: Matovu Musa | E28: 37.326389 | G28: NTUMWA SOLOMON | H28: 43.796296 | I28: 44.667245 | J28: 26.277778 | L28: 38.037368 | N28: Pre-Trip inspection defect closure
D29: Bwanga Gilbert | E29: 37.539683 | G29: Tsaale Hassan | I29: 43.464506 | J29: 32.626029 | L29: 38.045267 | N29: Prolonged meeting.
D30: NTUMWA SOLOMON | E30: 38.037368 | G30: Mugisha George | H30: 48.972222 | I30: 43.796296 | J30: 26.128472 | K30: 36.686508 | L30: 38.233932 | N30: Reconcile stock count delays
D31: Tsaale Hassan | E31: 38.045267 | G31: ZIWA ABASI | H31: 40.063657 | I31: 42.800926 | J31: 33.344907 | K31: 37.824074 | L31: 38.638468 | N31: Traffic at the exit gate.
D32: Mugisha George | E32: 38.233932 | G32: Luyaga Isaac | H32: 39.483025 | I32: 41.805556 | J32: 39.814815 | K32: 35.335648 | L32: 38.670139 | N32: unplanned trainings
D33: ZIWA ABASI | E33: 38.638468 | G33: Eriku Alipa | I33: 41.805556 | J33: 36.331019 | L33: 38.677249 | N33: Weigh bridge delays
D34: Luyaga Isaac | E34: 38.670139 | G34: Sentongo paul | I34: 42.469136 | J34: 34.126984 | L34: 38.819444
D35: Eriku Alipa | E35: 38.677249 | G35: Kyakulaga James | I35: 42.438973 | J35: 33.131614 | L35: 38.819444
D36: Sentongo paul | E36: 38.819444 | G36: SENTONG DAVID | H36: 46.284722 | I36: 42.386188 | J36: 34.47601 | K36: 32.59838 | L36: 38.819444
D37: Kyakulaga James | E37: 38.819444 | G37: Tumusiime Robert | H37: 40.3125 | I37: 42.800926 | J37: 40.3125 | K37: 36.402116 | L37: 38.819444
D38: SENTONG DAVID | E38: 38.819444 | G38: Kabanda Ronald | I38: 42.676505 | J38: 34.695767 | L38: 38.95216
D39: Tumusiime Robert | E39: 38.819444 | G39: Konge Husein | H39: 43.796296 | I39: 42.800926 | K39: 35.335648 | L39: 39.090909
D40: Kabanda Ronald | E40: 38.95216 | G40: Ngobi Fred | I40: 43.920718 | J40: 31.851852 | L40: 39.278846
...

Sheet Sheet6
B3: Column Labels
B4: January | C4: February | D4: March | E4: April | F4: May | G4: (blank) | H4: Grand Total
A5: Average of AVE Departure | B5: 43.986135 | C5: 42.703066 | D5: 30.284293 | E5: 31.940911 | F5: 31.362066 | H5: 36.065286

Sheet Sheet7
B3: Column Labels
B4: January | C4: February | D4: March | E4: April | F4: May | G4: (blank) | H4: Grand Total
A5: Average of AVE Arrival Time | B5: 55.873067 | C5: 55.160639 | D5: 50.415357 | E5: 43.227632 | F5: 42.146908 | H5: 49.886548

Sheet 2025
A3: Row Labels | B3: Average of AVE Departure | E3: Count of Comment AVE Departure | F3: Column Labels | W3: Row Labels | X3: Average of AVE Arrival Time | Z3: Count of Comment AVE Arrival Time | AA3: Column Labels
A4: January | B4: 43.986135 | E4: Row Labels | F4: Damaged stock replacement | G4: DJ failures | H4: Driver delays | I4: found another truck waiting to be cleared at the gate | J4: Jam at the weigh bridge | K4: Meeting Delays | L4: network failures | M4: pressure balancing | N4: Pre-Trip inspection defect closure | O4: Reconciling stock count delays | P4: stock recon delays | Q4: Unplanned Training | R4: Water top up | S4: (blank) | T4: Grand Total | W4: January | X4: 55.873067 | Z4: Row Labels | AA4: beer topup delays | AB4: dj completion delays | AC4: dj failures | AD4: dj failures at the gate | AE4: empties confirmation delays | AF4: Failed batteries at the gate | AG4: Fork Lift Breakdown | AH4: found another truck at the gate | AI4: found another truck waiting to offload | AJ4: fuel delays | AK4: fueling delays | AL4: loading delays | AM4: offloading delays | AN4: pre trip inspections | AO4: sorting delays | AP4: Traffic at gate | AQ4: Grand Total
A5: February | B5: 42.703066 | E5: January | F5: 1 | G5: 9 | H5: 1 | J5: 7 | K5: 2 | N5: 3 | O5: 3 | Q5: 3 | T5: 29 | W5: February | X5: 55.160639 | Z5: January | AD5: 2 | AH5: 1 | AJ5: 1 | AL5: 1 | AO5: 1 | AP5: 2 | AQ5: 8
A6: March | B6: 30.284293 | E6: February | G6: 1 | N6: 2 | T6: 3 | W6: March | X6: 50.415357 | Z6: February | AD6: 4 | AF6: 1 | AK6: 8 | AN6: 7 | AO6: 3 | AQ6: 23
A7: April | B7: 31.940911 | E7: March | G7: 3 | I7: 2 | J7: 1 | L7: 2 | M7: 8 | N7: 2 | P7: 4 | R7: 1 | T7: 23 | W7: April | X7: 43.227632 | Z7: March | AA7: 1 | AB7: 1 | AC7: 1 | AD7: 8 | AE7: 1 | AF7: 3 | AG7: 1 | AI7: 1 | AK7: 6 | AM7: 4 | AN7: 3 | AO7: 10 | AQ7: 40
A8: May | B8: 31.362066 | E8: April | G8: 8 | I8: 6 | J8: 6 | L8: 8 | M8: 18 | N8: 5 | P8: 5 | R8: 6 | T8: 62 | W8: May | X8: 42.146908 | Z8: April | AA8: 4 | AD8: 3 | AE8: 3 | AF8: 4 | AG8: 5 | AI8: 17 | AK8: 9 | AM8: 5 | AO8: 7 | AQ8: 57
A9: (blank) | E9: May | G9: 18 | I9: 9 | J9: 4 | L9: 7 | M9: 12 | N9: 4 | P9: 6 | R9: 10 | T9: 70 | W9: (blank) | Z9: May | AA9: 3 | AB9: 1 | AD9: 3 | AF9: 2 | AG9: 1 | AI9: 16 | AK9: 3 | AM9: 2 | AN9: 1 | AO9: 6 | AQ9: 38
A10: Grand Total | B10: 36.065286 | E10: (blank) | P10: 1 | T10: 1 | W10: Grand Total | X10: 49.886548 | Z10: Grand Total | AA10: 8 | AB10: 2 | AC10: 1 | AD10: 20 | AE10: 4 | AF10: 10 | AG10: 7 | AH10: 1 | AI10: 34 | AJ10: 1 | AK10: 26 | AL10: 1 | AM10: 11 | AN10: 11 | AO10: 27 | AP10: 2 | AQ10: 166
E11: Grand Total | F11: 1 | G11: 39 | H11: 1 | I11: 17 | J11: 18 | K11: 2 | L11: 17 | M11: 38 | N11: 16 | O11: 3 | P11: 16 | Q11: 3 | R11: 17 | T11: 188

Sheet DATA SOURCE
A1: Create Date | B1: Month Name | C1: Transporter | D1: Load Number | E1: Mode Of Capture | F1: Driver Name | G1: Truck Number | H1: Customer Name | I1: Vol Hl | J1: InvoiceNumber | K1: MWarehouse | L1: Budgeted KMs | M1: Actual KM | N1: KM Deviation | O1: Comment | P1: Clock in | Q1: Planned Departure Time | R1: DJ Departure Time | S1: Depature Deviation (min) | T1: AVE Departure | U1: Comment AVE Departure | V1: Arrival At Customer | W1: Departure Time from Customer | X1: Service Time At Customer | Y1: Comment TAT | Z1: Arrival At Depot | AA1: Clock Out | AB1: AVE Arrival Time | AC1: Comment AVE Arrival Time | AD1: Actual Days in Route | AE1: Bud Days in Route | AF1: Days in Rout Deviation | AG1: Total Hour Route | AH1: Driver Rest Hours In Route | AI1: Total WH | AJ1: TLP | AK1: D1 | AL1: D2 | AM1: D3 | AN1: D4 | AO1: Comment Ave TIR
A2: 45658 | B2: =TEXT(A2, "MMMM") -> January | D2: OM02L6Y5 | E2: Manual | F2: MUKOSE MUZAMIRU | G2: UBE 690K | H2: Kato Investment Ltd -Kagadi | I2: 151.68 | J2: A19778 | K2: OM | L2: 670 | M2: 612 | N2: -5 | P2: =R2-TIME(0,40,0) -> 45658.332 | Q2: 45658.312 | R2: 45658.36 | S2: =(R2-Q2)*86000/60 -> 67.685185 | T2: =(R2-P2)*86000/60 -> 39.814815 | V2: 45659.422 | W2: 45659.574 | X2: =(W2-V2)*84600/60 -> 214.4375 | Y2: space consquents | Z2: 45660.432 | AA2: =Z2+TIME(0,59,0) -> 45660.473 | AB2: =(AA2-Z2)*84600/60 -> 57.770833 | AD2: =Z2-R2 -> 2.0725833 | AE2: 2 | AF2: =AE2-AD2 -> -0.072583333 | AG2: =AD2*24 -> 49.742 | AH2: =AG2-AI2 -> 24 | AI2: =((Z2 - R2) * 24) - (INT(Z2 - R2) * 12) -> 25.742 | AJ2: =I2/AI2 -> 5.8923161
A3: 45658.846 | B3: =TEXT(A3, "MMMM") -> January | D3: OM7APO5RR | E3: DJ | F3: Stephen Musoke | G3: UBJ 375N | H3: Kabaco U Ltd-Mbarara | I3: 140.1 | J3: Z82022 | K3: OM | L3: 20 | M3: 14 | N3: 3 | P3: =R3-TIME(0,43,0) -> 45659.622 | Q3: 45659.321 | R3: 45659.651 | S3: =(R3-Q3)*86000/60 -> 473.7963 | T3: =(R3-P3)*86000/60 -> 42.800926 | V3: 45659.672 | W3: 45659.806 | X3: =(W3-V3)*84600/60 -> 189.95833 | Y3: Reached late and offloaded the next day | Z3: 45659.84 | AA3: 45659.879 | AB3: =(AA3-Z3)*84600/60 -> 54.833333 | AD3: =Z3-R3 -> 0.18888889 | AE3: 1 | AF3: =AE3-AD3 -> 0.81111111 | AG3: =AD3*24 -> 4.5333333 | AH3: =AG3-AI3 -> 0 | AI3: =((Z3 - R3) * 24) - (INT(Z3 - R3) * 12) -> 4.5333333 | AJ3: =I3/AI3 -> 30.904412
A4: 45658.846 | B4: =TEXT(A4, "MMMM") -> January | D4: OMCOX6YRR | E4: DJ | F4: Isaac Tumuhimbise | G4: UBE 287X | H4: Kabaco U Ltd-Mbarara | I4: 153.6 | J4: Z82023 | K4: OM | L4: 20 | M4: 13 | N4: =M4-L4 -> -7 | P4: =R4-TIME(0,37,0) -> 45659.449 | Q4: 45659.321 | R4: 45659.475 | S4: =(R4-Q4)*86000/60 -> 220.97222 | T4: =(R4-P4)*86000/60 -> 36.828704 | V4: 45659.501 | W4: 45659.694 | X4: =(W4-V4)*84600/60 -> 272.20833 | Y4: truck faulty | Z4: 45659.72 | AA4: 45659.761 | AB4: =(AA4-Z4)*84600/60 -> 57.770833 | AD4: =Z4-R4 -> 0.24513889 | AE4: 1 | AF4: =AE4-AD4 -> 0.75486111 | AG4: =AD4*24 -> 5.8833333 | AH4: =AG4-AI4 -> 0 | AI4: =((Z4 - R4) * 24) - (INT(Z4 - R4) * 12) -> 5.8833333 | AJ4: =I4/AI4 -> 26.107649
A5: 45658.847 | B5: =TEXT(A5, "MMMM") -> January | D5: OMZLGL1RR | E5: DJ | F5: James Kironde | G5: UBK 881R | H5: KATO INVESTMENTS LIMITED-MASAK | I5: 153.6 | J5: F15655 | K5: OM | L5: 340 | M5: =L5+2 -> 342 | N5: =M5-L5 -> 2 | P5: 45659.291 | Q5: 45659.176 | R5: 45659.317 | S5: =(R5-Q5)*86000/60 -> 202.06019 | T5: =(R5-P5)*86000/60 -> 37.824074 | V5: 45659.392 | W5: 45659.566 | X5: =(W5-V5)*84600/60 -> 245.77083 | Y5: slept at the RD and offloaded the next day | Z5: 45660.39 | AA5: =Z5+TIME(0,59,0) -> 45660.431 | AB5: =(AA5-Z5)*84600/60 -> 57.770833 | AD5: =Z5-R5 -> 1.0729167 | AE5: 1 | AF5: =AE5-AD5 -> -0.072916667 | AG5: =AD5*24 -> 25.75 | AH5: =AG5-AI5 -> 12 | AI5: =((Z5 - R5) * 24) - (INT(Z5 - R5) * 12) -> 13.75 | AJ5: =I5/AI5 -> 11.170909
A6: 45658.848 | B6: =TEXT(A6, "MMMM") -> January | D6: OM33KZQRR | E6: DJ | F6: Jacob Oneka | G6: UBE 422T | H6: Kato Investments Ltd-Bulenga | I6: 153.6 | J6: A19779 | K6: OM | L6: 560 | M6: =L6-1 -> 559 | N6: =M6-L6 -> -1 | P6: =R6-TIME(0,65,0) -> 45659.487 | Q6: 45658.896 | R6: 45659.533 | S6: =(R6-Q6)*86000/60 -> 912.75463 | T6: =(R6-P6)*86000/60 -> 64.699074 | U6: DJ failures | V6: 45660.448 | W6: 45660.649 | X6: =(W6-V6)*84600/60 -> 283.95833 | Y6: Waited for empties from trade | Z6: 45661.486 | AA6: =Z6+TIME(0,54,0) -> 45661.524 | AB6: =(AA6-Z6)*84600/60 -> 52.875 | AD6: =Z6-R6 -> 1.9534722 | AE6: 2 | AF6: =AE6-AD6 -> 0.046527778 | AG6: =AD6*24 -> 46.883333 | AH6: =AG6-AI6 -> 12 | AI6: =((Z6 - R6) * 24) - (INT(Z6 - R6) * 12) -> 34.883333 | AJ6: =I6/AI6 -> 4.4032489
A7: 45658.849 | B7: =TEXT(A7, "MMMM") -> January | D7: OMCP7C6RR | E7: Manual | F7: Kilabila Ismail | G7: UBE 419T | H7: RUGOMA TRADERS CO. LTD NTUNGAM | I7: 153.6 | J7: F15657 | K7: OM | L7: 130 | M7: =L7-1 -> 129 | N7: =M7-L7 -> -1 | P7: =R7-TIME(0,77,0) -> 45659.343 | Q7: 45659.349 | R7: 45659.396 | S7: =(R7-Q7)*86000/60 -> 67.685185 | T7: =(R7-P7)*86000/60 -> 76.643519 | U7: Jam at the weigh bridge | V7: 45659.5 | W7: 45659.709 | X7: =(W7-V7)*84600/60 -> 293.75 | Y7: Waited for empties from trade | Z7: 45659.799 | AA7: 45659.838 | AB7: =(AA7-Z7)*84600/60 -> 54.833333 | AD7: =Z7-R7 -> 0.40277778 | AE7: 1 | AF7: =AE7-AD7 -> 0.59722222 | AG7: =AD7*24 -> 9.6666667 | AH7: =AG7-AI7 -> 0 | AI7: =((Z7 - R7) * 24) - (INT(Z7 - R7) * 12) -> 9.6666667 | AJ7: =I7/AI7 -> 15.889655
A8: 45658.853 | B8: =TEXT(A8, "MMMM") -> January | D8: OMO39VURR | E8: DJ | F8: ALIPA EREKU | G8: UBK 858R | H8: KATO INVESTMENTS LTD-KATIKARA | I8: 133.44 | J8: A19781 | K8: OM | L8: 790 | M8: =L8+2 -> 792 | N8: =M8-L8 -> 2 | P8: =R8-TIME(0,40,0) -> 45658.844 | Q8: 45659.658 | R8: 45658.872 | S8: =(R8-Q8)*86000/60 -> -1126.7593 | T8: =(R8-P8)*86000/60 -> 39.814815 | V8: 45660.332 | W8: 45660.511 | X8: =(W8-V8)*84600/60 -> 252.625 | Y8: found another truck at the RD and offloaded the next day | Z8: 45661.477 | AA8: =Z8+TIME(0,59,0) -> 45661.518 | AB8: =(AA8-Z8)*84600/60 -> 57.770833 | AD8: =Z8-R8 -> 2.6048611 | AE8: 3 | AF8: =AE8-AD8 -> 0.39513889 | AG8: =AD8*24 -> 62.516667 | AH8: =AG8-AI8 -> 24 | AI8: =((Z8 - R8) * 24) - (INT(Z8 - R8) * 12) -> 38.516667 | AJ8: =I8/AI8 -> 3.4644743
A9: 45659.74 | B9: =TEXT(A9, "MMMM") -> January | D9: OMY25R8RR | E9: DJ | F9: Benon Ssempijja | G9: UAY 526V | H9: Ntale and Sons | I9: 153.6 | J9: A19789 | K9: OM | L9: 810 | M9: =L9+2 -> 812 | N9: =M9-L9 -> 2 | P9: =R9-TIME(0,39,0) -> 45660.321 | Q9: 45659.812 | R9: 45660.348 | S9: =(R9-Q9)*86000/60 -> 767.43056 | T9: =(R9-P9)*86000/60 -> 38.819444 | V9: 45660.866 | W9: 45661.583 | X9: =(W9-V9)*84600/60 -> 1010.5 | Y9: Waited for empties from trade | Z9: 45662.633 | AA9: 45662.667 | AB9: =(AA9-Z9)*84600/60 -> 47.979167 | AD9: =Z9-R9 -> 2.2847222 | AE9: 3 | AF9: =AE9-AD9 -> 0.71527778 | AG9: =AD9*24 -> 54.833333 | AH9: =AG9-AI9 -> 24 | AI9: =((Z9 - R9) * 24) - (INT(Z9 - R9) * 12) -> 30.833333 | AJ9: =I9/AI9 -> 4.9816216
A10: 45659.74 | B10: =TEXT(A10, "MMMM") -> January | D10: OM84GFKRR | E10: DJ | F10: Kilabila Ismail | G10: UBE 419T | H10: KATO INVESTMENTS LIMITED-MASAK | I10: 153.6 | J10: F15658 | K10: OM | L10: 340 | M10: 340 | N10: =M10-L10 -> 0 | P10: =R10-TIME(0,43,0) -> 45659.751 | Q10: 45660.176 | R10: 45659.781 | S10: =(R10-Q10)*86000/60 -> -567.36111 | T10: =(R10-P10)*86000/60 -> 42.800926 | V10: 45660.506 | W10: 45660.631 | X10: =(W10-V10)*84600/60 -> 176.25 | Z10: 45661.444 | AA10: 45661.483 | AB10: =(AA10-Z10)*84600/60 -> 54.833333 | AD10: =Z10-R10 -> 1.6638889 | AE10: 2 | AF10: =AE10-AD10 -> 0.33611111 | AG10: =AD10*24 -> 39.933333 | AH10: =AG10-AI10 -> 12 | AI10: =((Z10 - R10) * 24) - (INT(Z10 - R10) * 12) -> 27.933333 | AJ10: =I10/AI10 -> 5.4988067
A11: 45659.967 | B11: =TEXT(A11, "MMMM") -> January | D11: OMN00PNRR | E11: DJ | F11: James Kironde | G11: UBK 881R | H11: Sawan Distributors Ltd-Nabingo | I11: 153.6 | J11: A19800 | K11: OM | L11: 560 | M11: =L11+2 -> 562 | N11: =M11-L11 -> 2 | P11: =R11-TIME(0,59,0) -> 45660.562 | Q11: 45660.333 | R11: 45660.603 | S11: =(R11-Q11)*86000/60 -> 387.19907 | T11: =(R11-P11)*86000/60 -> 58.726852 | U11: DJ failures | V11: 45660.881 | W11: 45661.524 | X11: =(W11-V11)*84600/60 -> 906.70833 | Y11: space consquents | Z11: 45663.591 | AA11: =Z11+TIME(0,59,0) -> 45663.632 | AB11: =(AA11-Z11)*84600/60 -> 57.770833 | AD11: =Z11-R11 -> 2.9875 | AE11: 2 | AF11: =AE11-AD11 -> -0.9875 | AG11: =AD11*24 -> 71.7 | AH11: =AG11-AI11 -> 24 | AI11: =((Z11 - R11) * 24) - (INT(Z11 - R11) * 12) -> 47.7 | AJ11: =I11/AI11 -> 3.2201258
A12: 45659.968 | B12: =TEXT(A12, "MMMM") -> January | D12: OM8F9LXRR | E12: DJ | F12: Bisaso Ronald | G12: UBK 875R | H12: Kabaco U Ltd-Mbarara | I12: 149.4 | J12: Z82038 | K12: OM | L12: 20 | M12: =L12+2 -> 22 | N12: =M12-L12 -> 2 | P12: 45660.583 | Q12: 45660.333 | R12: 45660.609 | S12: =(R12-Q12)*86000/60 -> 395.16204 | T12: =(R12-P12)*86000/60 -> 37.824074 | V12: 45660.658 | W12: 45660.782 | X12: =(W12-V12)*84600/60 -> 175.27083 | Z12: 45660.803 | AA12: 45660.839 | AB12: =(AA12-Z12)*84600/60 -> 50.916667 | AD12: =Z12-R12 -> 0.19375 | AE12: 2 | AF12: =AE12-AD12 -> 1.80625 | AG12: =AD12*24 -> 4.65 | AH12: =AG12-AI12 -> 0 | AI12: =((Z12 - R12) * 24) - (INT(Z12 - R12) * 12) -> 4.65 | AJ12: =I12/AI12 -> 32.129032
A13: 45659.969 | B13: =TEXT(A13, "MMMM") -> January | D13: OMHX7MPRR | E13: DJ | F13: Stephen Musoke | G13: UBJ 375N | H13: Kobusinge Steven-Kamwenge | I13: 153.6 | J13: Z82039 | K13: OM | L13: 230 | M13: 230 | N13: =M13-L13 -> 0 | P13: 45660.383 | Q13: 45660.375 | R13: 45660.413 | S13: =(R13-Q13)*86000/60 -> 54.74537 | T13: =(R13-P13)*86000/60 -> 43.796296 | V13: 45660.549 | W13: 45660.714 | X13: =(W13-V13)*84600/60 -> 233.04167 | Y13: Waited for empties from trade | Z13: 45661.398 | AA13: =Z13+TIME(0,59,0) -> 45661.439 | AB13: =(AA13-Z13)*84600/60 -> 57.770833 | AD13: =Z13-R13 -> 0.98472222 | AE13: 2 | AF13: =AE13-AD13 -> 1.0152778 | AG13: =AD13*24 -> 23.633333 | AH13: =AG13-AI13 -> 0 | AI13: =((Z13 - R13) * 24) - (INT(Z13 - R13) * 12) -> 23.633333 | AJ13: =I13/AI13 -> 6.4992948
A14: 45659.969 | B14: =TEXT(A14, "MMMM") -> January | D14: OMVZ7HGRR | E14: DJ | F14: Isaac Tumuhimbise | G14: UBE 287X | H14: Agaba Services | I14: 153.6 | J14: F15659 | K14: OM | L14: 302 | M14: 293 | N14: =M14-L14 -> -9 | P14: =R14-TIME(0,57,0) -> 45660.262 | Q14: 45660.354 | R14: 45660.301 | S14: =(R14-Q14)*86000/60 -> -75.648148 | T14: =(R14-P14)*86000/60 -> 56.736111 | U14: Meeting Delays | V14: 45660.526 | W14: 45660.607 | X14: =(W14-V14)*84600/60 -> 114.5625 | Z14: 45661.358 | AA14: 45661.394 | AB14: =(AA14-Z14)*84600/60 -> 50.916667 | AD14: =Z14-R14 -> 1.0569444 | AE14: 2 | AF14: =AE14-AD14 -> 0.94305556 | AG14: =AD14*24 -> 25.366667 | AH14: =AG14-AI14 -> 12 | AI14: =((Z14 - R14) * 24) - (INT(Z14 - R14) * 12) -> 13.366667 | AJ14: =I14/AI14 -> 11.491272
A15: 45659.97 | B15: =TEXT(A15, "MMMM") -> January | D15: OM976EURR | E15: DJ | F15: Mugisha George | G15: UAV 203T | H15: Kobusinge Acaali- Kyenjojo | I15: 153.6 | J15: Z82040 | K15: OM | L15: 480 | M15: 469 | N15: =M15-L15 -> -11 | P15: =R15-TIME(0,76,0) -> 45660.37 | Q15: 45661.137 | R15: 45660.423 | S15: =(R15-Q15)*86000/60 -> -1023.2407 | T15: =(R15-P15)*86000/60 -> 75.648148 | U15: Damaged stock replacement | V15: 45661.351 | W15: 45661.568 | X15: =(W15-V15)*84600/60 -> 305.5 | Y15: Waited for empties from trade | Z15: 45662.418 | AA15: =Z15+TIME(0,57,0) -> 45662.458 | AB15: =(AA15-Z15)*84600/60 -> 55.8125 | AD15: =Z15-R15 -> 1.9951389 | AE15: 2 | AF15: =AE15-AD15 -> 0.0048611111 | AG15: =AD15*24 -> 47.883333 | AH15: =AG15-AI15 -> 12 | AI15: =((Z15 - R15) * 24) - (INT(Z15 - R15) * 12) -> 35.883333 | AJ15: =I15/AI15 -> 4.2805388
A16: 45660 | B16: =TEXT(A16, "MMMM") -> January | D16: OM02L7BP | E16: Manual | G16: UBE 678K | H16: Ntale and Sons Ltd-Kakiri | I16: 156 | J16: A19821 | K16: OM | L16: 620 | M16: 612 | N16: =M16-L16 -> -8 | P16: =R16-TIME(0,40,0) -> 45660.337 | Q16: 45660.312 | R16: 45660.365 | S16: =(R16-Q16)*86000/60 -> 74.652778 | T16: =(R16-P16)*86000/60 -> 39.814815 | V16: 45660.885 | W16: =V16+TIME(0,367,0) -> 45661.14 | X16: =(W16-V16)*84600/60 -> 359.35417 | Y16: Waited for empties from trade | Z16: 45662.595 | AA16: =Z16+TIME(0,57,0) -> 45662.635 | AB16: =(AA16-Z16)*84600/60 -> 55.8125 | AD16: =Z16-R16 -> 2.2308333 | AE16: 3 | AF16: =AE16-AD16 -> 0.76916667 | AG16: =AD16*24 -> 53.54 | AH16: =AG16-AI16 -> 24 | AI16: =((Z16 - R16) * 24) - (INT(Z16 - R16) * 12) -> 29.54 | AJ16: =I16/AI16 -> 5.2809749
A17: 45660 | B17: =TEXT(A17, "MMMM") -> January | D17: OM02L7BK | E17: Manual | G17: UBE 678K | H17: Kato Investments Ltd- Kakumiro | I17: 156 | J17: A19818 | K17: OM | L17: 765 | M17: =L17+2 -> 767 | N17: =M17-L17 -> 2 | P17: =R17-TIME(0,41,0) -> 45660.342 | Q17: 45660.312 | R17: 45660.37 | S17: =(R17-Q17)*86000/60 -> 82.615741 | T17: =(R17-P17)*86000/60 -> 40.810185 | V17: 45660.745 | W17: =V17+TIME(0,153,0) -> 45660.851 | X17: =(W17-V17)*84600/60 -> 149.8125 | Z17: 45661.88 | AA17: =Z17+TIME(0,59,0) -> 45661.921 | AB17: =(AA17-Z17)*84600/60 -> 57.770833 | AD17: =Z17-R17 -> 1.5101667 | AE17: 3 | AF17: =AE17-AD17 -> 1.4898333 | AG17: =AD17*24 -> 36.244 | AH17: =AG17-AI17 -> 12 | AI17: =((Z17 - R17) * 24) - (INT(Z17 - R17) * 12) -> 24.244 | AJ17: =I17/AI17 -> 6.4345818
A18: 45660 | B18: =TEXT(A18, "MMMM") -> January | D18: OM02L7BR | E18: Manual | F18: MUKOSE MUZAMIRU | G18: UBE 690K | H18: Kabaco U Ltd | I18: 156 | J18: Z82048 | K18: OM | L18: 320 | M18: 319 | N18: =M18-L18 -> -1 | P18: =R18-TIME(0,43,0) -> 45660.333 | Q18: 45660.312 | R18: 45660.362 | S18: =(R18-Q18)*86000/60 -> 71.666667 | T18: =(R18-P18)*86000/60 -> 42.800926 | V18: 45660.612 | W18: =V18+TIME(0,161,0) -> 45660.724 | X18: =(W18-V18)*84600/60 -> 157.64583 | Z18: 45661.492 | AA18: 45661.533 | AB18: =(AA18-Z18)*84600/60 -> 57.770833 | AD18: =Z18-R18 -> 1.1293056 | AE18: 2 | AF18: =AE18-AD18 -> 0.87069444 | AG18: =AD18*24 -> 27.103333 | AH18: =AG18-AI18 -> 12 | AI18: =((Z18 - R18) * 24) - (INT(Z18 - R18) * 12) -> 15.103333 | AJ18: =I18/AI18 -> 10.328846
A19: 45660 | B19: =TEXT(A19, "MMMM") -> January | D19: OM02L777 | E19: Manual | G19: UBP 311H | H19: Kato Investments Ltd- Kyegegwa | I19: 156 | J19: A19812 | K19: OM | L19: 600 | M19: 591 | N19: =M19-L19 -> -9 | P19: =R19-TIME(0,77,0) -> 45660.312 | Q19: 45660.312 | R19: 45660.365 | S19: =(R19-Q19)*86000/60 -> 75.648148 | T19: =(R19-P19)*86000/60 -> 76.643519 | U19: Pre-Trip inspection defect closure | V19: 45661.462 | W19: =V19+TIME(0,175,0) -> 45661.584 | X19: =(W19-V19)*84600/60 -> 171.35417 | Z19: 45661.886 | AA19: =Z19+TIME(0,56,0) -> 45661.925 | AB19: =(AA19-Z19)*84600/60 -> 54.833333 | AD19: =Z19-R19 -> 1.5208333 | AE19: 2 | AF19: =AE19-AD19 -> 0.47916667 | AG19: =AD19*24 -> 36.5 | AH19: =AG19-AI19 -> 12 | AI19: =((Z19 - R19) * 24) - (INT(Z19 - R19) * 12) -> 24.5 | AJ19: =I19/AI19 -> 6.3673469
A20: 45660 | B20: =TEXT(A20, "MMMM") -> January | D20: OM02L77A | E20: Manual | G20: UBP 311H | H20: Kobusinge Steven-FPortal | I20: 156 | J20: Z82042 | K20: OM | L20: 390 | M20: 386 | N20: =M20-L20 -> -4 | P20: =R20-TIME(0,43,0) -> 45660.336 | Q20: 45660.312 | R20: 45660.366 | S20: =(R20-Q20)*86000/60 -> 76.643519 | T20: =(R20-P20)*86000/60 -> 42.800926 | V20: 45661.428 | W20: =V20+TIME(0,153,0) -> 45661.535 | X20: =(W20-V20)*84600/60 -> 149.8125 | Z20: 45662.372 | AA20: =Z20+TIME(0,59,0) -> 45662.413 | AB20: =(AA20-Z20)*84600/60 -> 57.770833 | AD20: =Z20-R20 -> 2.0065 | AE20: 2 | AF20: =AE20-AD20 -> -0.0065 | AG20: =AD20*24 -> 48.156 | AH20: =AG20-AI20 -> 24 | AI20: =((Z20 - R20) * 24) - (INT(Z20 - R20) * 12) -> 24.156 | AJ20: =I20/AI20 -> 6.4580229
A21: 45660 | B21: =TEXT(A21, "MMMM") -> January | D21: OM02L7BL | E21: Manual | F21: Ekwalikwa Yusuf | G21: UBP 311H | H21: Kobusinge Steven-Kamwenge | I21: 156 | J21: Z82047 | K21: OM | L21: 230 | M21: =L21+2 -> 232 | N21: =M21-L21 -> 2 | P21: =R21-TIME(0,39,0) -> 45660.349 | Q21: 45660.312 | R21: 45660.376 | S21: =(R21-Q21)*86000/60 -> 91.574074 | T21: =(R21-P21)*86000/60 -> 38.819444 | V21: 45661.397 | W21: =V21+TIME(0,149,0) -> 45661.501 | X21: =(W21-V21)*84600/60 -> 145.89583 | Z21: 45661.822 | AA21: =Z21+TIME(0,52,0) -> 45661.858 | AB21: =(AA21-Z21)*84600/60 -> 50.916667 | AD21: =Z21-R21 -> 1.4451389 | AE21: 2 | AF21: =AE21-AD21 -> 0.55486111 | AG21: =AD21*24 -> 34.683333 | AH21: =AG21-AI21 -> 12 | AI21: =((Z21 - R21) * 24) - (INT(Z21 - R21) * 12) -> 22.683333 | AJ21: =I21/AI21 -> 6.8772961
A22: 45660 | B22: =TEXT(A22, "MMMM") -> January | D22: OM02L7BM | E22: Manual | F22: Ekwalikwa Yusuf | G22: UBP 311H | H22: Kato Investment Ltd -Mubende | I22: 154.344 | J22: A19820 | K22: OM | L22: 680 | M22: =L22+2 -> 682 | N22: =M22-L22 -> 2 | P22: =R22-TIME(0,43,0) -> 45660.344 | Q22: 45660.312 | R22: 45660.374 | S22: =(R22-Q22)*86000/60 -> 87.592593 | T22: =(R22-P22)*86000/60 -> 42.800926 | V22: 45661.469 | W22: =V22+TIME(0,175,0) -> 45661.59 | X22: =(W22-V22)*84600/60 -> 171.35417 | Z22: 45662.787 | AA22: 45662.819 | AB22: =(AA22-Z22)*84600/60 -> 46.020833 | AD22: =Z22-R22 -> 2.4130556 | AE22: 2 | AF22: =AE22-AD22 -> -0.41305556 | AG22: =AD22*24 -> 57.913333 | AH22: =AG22-AI22 -> 24 | AI22: =((Z22 - R22) * 24) - (INT(Z22 - R22) * 12) -> 33.913333 | AJ22: =I22/AI22 -> 4.5511303
A23: 45660 | B23: =TEXT(A23, "MMMM") -> January | D23: OM02L77B | E23: Manual | G23: UBP 311H | H23: KATO INVESTMENTS LTD-KATIKARA | I23: 156 | J23: A19813 | K23: OM | L23: 790 | M23: =L23+2 -> 792 | N23: =M23-L23 -> 2 | P23: 45660.332 | Q23: 45660.312 | R23: 45660.36 | S23: =(R23-Q23)*86000/60 -> 67.685185 | T23: =(R23-P23)*86000/60 -> 39.814815 | V23: 45661.412 | W23: =V23+TIME(0,336,0) -> 45661.645 | X23: =(W23-V23)*84600/60 -> 329 | Y23: found another truck to be offloaded | Z23: 45662.819 | AA23: 45662.86 | AB23: =(AA23-Z23)*84600/60 -> 57.770833 | AD23: =Z23-R23 -> 2.4597222 | AE23: 3 | AF23: =AE23-AD23 -> 0.54027778 | AG23: =AD23*24 -> 59.033333 | AH23: =AG23-AI23 -> 24 | AI23: =((Z23 - R23) * 24) - (INT(Z23 - R23) * 12) -> 35.033333 | AJ23: =I23/AI23 -> 4.452902
A24: 45660 | B24: =TEXT(A24, "MMMM") -> January | D24: OM02L7BH | E24: Manual | G24: UBP 311H | H24: Kobusinge Steven-FPortal | I24: 156 | J24: Z82046 | K24: OM | L24: 390 | M24: 386 | N24: =M24-L24 -> -4 | P24: =R24-TIME(0,63,0) -> 45660.316 | Q24: 45660.312 | R24: 45660.36 | S24: =(R24-Q24)*86000/60 -> 67.685185 | T24: =(R24-P24)*86000/60 -> 62.708333 | U24: Meeting Delays | V24: 45661.422 | W24: =V24+TIME(0,153,0) -> 45661.528 | X24: =(W24-V24)*84600/60 -> 149.8125 | Z24: 45662.396 | AA24: =Z24+TIME(0,57,0) -> 45662.436 | AB24: =(AA24-Z24)*84600/60 -> 55.8125 | AD24: =Z24-R24 -> 2.0365 | AE24: 2 | AF24: =AE24-AD24 -> -0.0365 | AG24: =AD24*24 -> 48.876 | AH24: =AG24-AI24 -> 24 | AI24: =((Z24 - R24) * 24) - (INT(Z24 - R24) * 12) -> 24.876 | AJ24: =I24/AI24 -> 6.2711047
A25: 45660.501 | B25: =TEXT(A25, "MMMM") -> January | D25: OMJVKLYRR | E25: DJ | F25: Abel Mark naffa | G25: UBJ 415C | H25: KATO INVESTMENTS LIMITED-MASAK | I25: 153.6 | J25: F15660 | K25: OM | L25: 340 | M25: 255 | N25: =M25-L25 -> -85 | P25: =R25-TIME(0,35,0) -> 45660.68 | Q25: 45661.176 | R25: 45660.704 | S25: =(R25-Q25)*86000/60 -> -676.85185 | T25: =(R25-P25)*86000/60 -> 34.837963 | V25: 45661.5 | W25: =V25+TIME(0,149,0) -> 45661.603 | X25: =(W25-V25)*84600/60 -> 145.89583 | Z25: 45663.544 | AA25: =Z25+TIME(0,59,0) -> 45663.585 | AB25: =(AA25-Z25)*84600/60 -> 57.770833 | AD25: =Z25-R25 -> 2.8395833 | AE25: 2 | AF25: =AE25-AD25 -> -0.83958333 | AG25: =AD25*24 -> 68.15 | AH25: =AG25-AI25 -> 24 | AI25: =((Z25 - R25) * 24) - (INT(Z25 - R25) * 12) -> 44.15 | AJ25: =I25/AI25 -> 3.4790487
A26: 45660.503 | B26: =TEXT(A26, "MMMM") -> January | D26: OMFII1DRR | E26: Manual | F26: Angello Lumala | G26: UAV 051U | H26: KATO INVESTMENTS LTD- KALISIZO | I26: 153.6 | J26: F15661 | K26: OM | L26: 350 | M26: 351 | N26: =M26-L26 -> 1 | P26: =R26-TIME(0,43,0) -> 45661.023 | Q26: 45661.003 | R26: 45661.053 | S26: =(R26-Q26)*86000/60 -> 71.666667 | T26: =(R26-P26)*86000/60 -> 42.800926 | V26: 45661.344 | W26: =V26+TIME(0,153,0) -> 45661.45 | X26: =(W26-V26)*84600/60 -> 149.8125 | Z26: 45661.761 | AA26: 45661.802 | AB26: =(AA26-Z26)*84600/60 -> 57.770833 | AD26: =Z26-R26 -> 0.70833333 | AE26: 2 | AF26: =AE26-AD26 -> 1.2916667 | AG26: =AD26*24 -> 17 | AH26: =AG26-AI26 -> 0 | AI26: =((Z26 - R26) * 24) - (INT(Z26 - R26) * 12) -> 17 | AJ26: =I26/AI26 -> 9.0352941
A27: 45660.505 | B27: =TEXT(A27, "MMMM") -> January | D27: OMY3M6PRR | E27: DJ | F27: Tumusiime Robert | G27: UBJ 988D | H27: RUGOMA TRADERS CO. LTD NTUNGAM | I27: 153.6 | J27: F15662 | K27: OM | L27: 130 | M27: =L27-1 -> 129 | N27: =M27-L27 -> -1 | P27: =R27-TIME(0,39,0) -> 45660.726 | Q27: 45661.26 | R27: 45660.753 | S27: =(R27-Q27)*86000/60 -> -727.61574 | T27: =(R27-P27)*86000/60 -> 38.819444 | V27: 45661.332 | W27: =V27+TIME(0,161,0) -> 45661.444 | X27: =(W27-V27)*84600/60 -> 157.64583 | Z27: 45661.714 | AA27: 45661.755 | AB27: =(AA27-Z27)*84600/60 -> 57.770833 | AD27: =Z27-R27 -> 0.96111111 | AE27: 1 | AF27: =AE27-AD27 -> 0.038888889 | AG27: =AD27*24 -> 23.066667 | AH27: =AG27-AI27 -> 0 | AI27: =((Z27 - R27) * 24) - (INT(Z27 - R27) * 12) -> 23.066667 | AJ27: =I27/AI27 -> 6.6589595
A28: 45660.506 | B28: =TEXT(A28, "MMMM") -> January | D28: OM0MCP3RR | E28: DJ | F28: SULAIMAN MUBIRU | G28: UBK 862R | H28: Boniface Harera | I28: 156 | J28: F15663 | K28: OM | L28: 470 | M28: =L28-1 -> 469 | N28: =M28-L28 -> -1 | P28: =R28-TIME(0,53,0) -> 45660.608 | Q28: 45661.062 | R28: 45660.644 | S28: =(R28-Q28)*86000/60 -> -599.21296 | T28: =(R28-P28)*86000/60 -> 52.75463 | U28: Jam at the weigh bridge | V28: 45661.431 | W28: =V28+TIME(0,175,0) -> 45661.553 | X28: =(W28-V28)*84600/60 -> 171.35417 | Z28: 45661.427 | AA28: =Z28+TIME(0,54,0) -> 45661.465 | AB28: =(AA28-Z28)*84600/60 -> 52.875 | AD28: =Z28-R28 -> 0.78263889 | AE28: 2 | AF28: =AE28-AD28 -> 1.2173611 | AG28: =AD28*24 -> 18.783333 | AH28: =AG28-AI28 -> 0 | AI28: =((Z28 - R28) * 24) - (INT(Z28 - R28) * 12) -> 18.783333 | AJ28: =I28/AI28 -> 8.3052351
A29: 45660.855 | B29: =TEXT(A29, "MMMM") -> January | D29: OMHN31TRR | E29: DJ | F29: Konge Husein | G29: UBJ 707D | H29: Kabaco U Ltd-Mbarara | I29: 151.8 | J29: Z82049 | K29: OM | L29: 20 | M29: 14 | N29: =M29-L29 -> -6 | P29: =R29-TIME(0,53,0) -> 45661.312 | Q29: 45661.321 | R29: 45661.349 | S29: =(R29-Q29)*86000/60 -> 39.814815 | T29: =(R29-P29)*86000/60 -> 52.75463 | U29: Jam at the weigh bridge | V29: 45661.384 | W29: =V29+TIME(0,320,0) -> 45661.606 | X29: =(W29-V29)*84600/60 -> 313.33333 | Y29: Waited for empties from trade | Z29: 45661.592 | AA29: 45661.624 | AB29: =(AA29-Z29)*84600/60 -> 46.020833 | AD29: =Z29-R29 -> 0.24305556 | AE29: 2 | AF29: =AE29-AD29 -> 1.7569444 | AG29: =AD29*24 -> 5.8333333 | AH29: =AG29-AI29 -> 0 | AI29: =((Z29 - R29) * 24) - (INT(Z29 - R29) * 12) -> 5.8333333 | AJ29: =I29/AI29 -> 26.022857
A30: 45660.86 | B30: =TEXT(A30, "MMMM") -> January | D30: OM4WLDZRR | E30: Manual | F30: Kabene John | G30: UBA 523T | H30: RUGOMA TRADERS CO. LTD NTUNGAM | I30: 153.6 | J30: F15664 | K30: OM | L30: 130 | M30: =L30-1 -> 129 | N30: =M30-L30 -> -1 | P30: =R30-TIME(0,43,0) -> 45661.377 | Q30: 45661.36 | R30: 45661.407 | S30: =(R30-Q30)*86000/60 -> 67.685185 | T30: =(R30-P30)*86000/60 -> 42.800926 | V30: 45661.502 | W30: =V30+TIME(0,167,0) -> 45661.618 | X30: =(W30-V30)*84600/60 -> 163.52083 | Z30: 45661.777 | AA30: =Z30+TIME(0,59,0) -> 45661.818 | AB30: =(AA30-Z30)*84600/60 -> 57.770833 | AD30: =Z30-R30 -> 0.36944444 | AE30: 1 | AF30: =AE30-AD30 -> 0.63055556 | AG30: =AD30*24 -> 8.8666667 | AH30: =AG30-AI30 -> 0 | AI30: =((Z30 - R30) * 24) - (INT(Z30 - R30) * 12) -> 8.8666667 | AJ30: =I30/AI30 -> 17.323308
A31: 45660.863 | B31: =TEXT(A31, "MMMM") -> January | D31: OMF1PUWRR | E31: DJ | F31: Bisaso Ronald | G31: UBK 875R | H31: Ntale and Sons | I31: 151.944 | J31: A19824 | K31: OM | L31: 810 | M31: =L31-1 -> 809 | N31: =M31-L31 -> -1 | P31: =R31-TIME(0,39,0) -> 45661.343 | Q31: 45660.896 | R31: 45661.37 | S31: =(R31-Q31)*86000/60 -> 679.83796 | T31: =(R31-P31)*86000/60 -> 38.819444 | V31: 45663.606 | W31: =V31+TIME(0,153,0) -> 45663.712 | X31: =(W31-V31)*84600/60 -> 149.8125 | Z31: 45664.862 | AA31: =Z31+TIME(0,59,0) -> 45664.903 | AB31: =(AA31-Z31)*84600/60 -> 57.770833 | AD31: =Z31-R31 -> 3.4916667 | AE31: 3 | AF31: =AE31-AD31 -> -0.49166667 | AG31: =AD31*24 -> 83.8 | AH31: =AG31-AI31 -> 36 | AI31: =((Z31 - R31) * 24) - (INT(Z31 - R31) * 12) -> 47.8 | AJ31: =I31/AI31 -> 3.1787448
A32: 45660.863 | B32: =TEXT(A32, "MMMM") -> January | D32: OM7HSU6RR | E32: DJ | F32: Isaac Tumuhimbise | G32: UBE 287X | H32: KATO INVESTMENTS LIMITED-MASAK | I32: 153.6 | J32: F15665 | K32: OM | L32: 340 | M32: 296 | N32: =M32-L32 -> -44 | P32: =R32-TIME(0,40,0) -> 45661.469 | Q32: 45661.176 | R32: 45661.497 | S32: =(R32-Q32)*86000/60 -> 459.86111 | T32: =(R32-P32)*86000/60 -> 39.814815 | V32: 45662.378 | W32: =V32+TIME(0,175,0) -> 45662.5 | X32: =(W32-V32)*84600/60 -> 171.35417 | Z32: 45662.665 | AA32: =Z32+TIME(0,57,0) -> 45662.705 | AB32: =(AA32-Z32)*84600/60 -> 55.8125 | AD32: =Z32-R32 -> 1.1680556 | AE32: 2 | AF32: =AE32-AD32 -> 0.83194444 | AG32: =AD32*24 -> 28.033333 | AH32: =AG32-AI32 -> 12 | AI32: =((Z32 - R32) * 24) - (INT(Z32 - R32) * 12) -> 16.033333 | AJ32: =I32/AI32 -> 9.5800416
A33: 45660.864 | B33: =TEXT(A33, "MMMM") -> January | D33: OMS5GYURR | E33: DJ | F33: NAMINYA SIRAJE | G33: UBP 301H | H33: Boniface Harera | I33: 156 | J33: F15666 | K33: OM | L33: 470 | M33: =L33-1 -> 469 | N33: =M33-L33 -> -1 | P33: =R33-TIME(0,40,0) -> 45660.81 | Q33: 45661.062 | R33: 45660.838 | S33: =(R33-Q33)*86000/60 -> -321.50463 | T33: =(R33-P33)*86000/60 -> 39.814815 | V33: 45663.572 | W33: =V33+TIME(0,167,0) -> 45663.688 | X33: =(W33-V33)*84600/60 -> 163.52083 | Z33: 45664.653 | AA33: 45664.687 | AB33: =(AA33-Z33)*84600/60 -> 47.979167 | AD33: =Z33-R33 -> 3.8145833 | AE33: 2 | AF33: =AE33-AD33 -> -1.8145833 | AG33: =AD33*24 -> 91.55 | AH33: =AG33-AI33 -> 36 | AI33: =((Z33 - R33) * 24) - (INT(Z33 - R33) * 12) -> 55.55 | AJ33: =I33/AI33 -> 2.8082808
A34: 45660.864 | B34: =TEXT(A34, "MMMM") -> January | D34: OMF7GZSRR | E34: DJ | F34: BYEKWASO TWAHA | G34: UBE 680K | H34: Kato Investments Ltd-Bulenga | I34: 156 | J34: A19825 | K34: OM | L34: 560 | M34: 507 | N34: =M34-L34 -> -53 | P34: =R34-TIME(0,40,0) -> 45660.826 | Q34: 45660.896 | R34: 45660.853 | S34: =(R34-Q34)*86000/60 -> -60.717593 | T34: =(R34-P34)*86000/60 -> 39.814815 | V34: 45661.69 | W34: =V34+TIME(0,175,0) -> 45661.811 | X34: =(W34-V34)*84600/60 -> 171.35417 | Z34: 45662.419 | AA34: =Z34+TIME(0,56,0) -> 45662.458 | AB34: =(AA34-Z34)*84600/60 -> 54.833333 | AD34: =Z34-R34 -> 1.5659722 | AE34: 3 | AF34: =AE34-AD34 -> 1.4340278 | AG34: =AD34*24 -> 37.583333 | AH34: =AG34-AI34 -> 12 | AI34: =((Z34 - R34) * 24) - (INT(Z34 - R34) * 12) -> 25.583333 | AJ34: =I34/AI34 -> 6.0977199
A35: 45660.985 | B35: =TEXT(A35, "MMMM") -> January | D35: OMUDTTERR | E35: DJ | F35: Kilabila Ismail | G35: UBE 419T | H35: Rugoma Traders-Kanungu/Kihihi | I35: 153.6 | J35: F15667 | K35: OM | L35: 414 | M35: =L35-1 -> 413 | N35: =M35-L35 -> -1 | P35: =R35-TIME(0,43,0) -> 45661.768 | Q35: 45661.354 | R35: 45661.798 | S35: =(R35-Q35)*86000/60 -> 636.04167 | T35: =(R35-P35)*86000/60 -> 42.800926 | V35: 45662.452 | W35: =V35+TIME(0,317,0) -> 45662.672 | X35: =(W35-V35)*84600/60 -> 310.39583 | Y35: Waited for empties from trade | Z35: 45663.47 | AA35: =Z35+TIME(0,54,0) -> 45663.508 | AB35: =(AA35-Z35)*84600/60 -> 52.875 | AD35: =Z35-R35 -> 1.6722222 | AE35: 2 | AF35: =AE35-AD35 -> 0.32777778 | AG35: =AD35*24 -> 40.133333 | AH35: =AG35-AI35 -> 12 | AI35: =((Z35 - R35) * 24) - (INT(Z35 - R35) * 12) -> 28.133333 | AJ35: =I35/AI35 -> 5.4597156
A36: 45660.986 | B36: =TEXT(A36, "MMMM") -> January | D36: OM8Y8XJRR | E36: DJ | F36: Stephen Musoke | G36: UBJ 375N | H36: Agaba Services | I36: 153.6 | J36: F15668 | K36: OM | L36: 302 | M36: 290 | N36: =M36-L36 -> -12 | P36: =R36-TIME(0,40,0) -> 45661.556 | Q36: 45661.354 | R36: 45661.583 | S36: =(R36-Q36)*86000/60 -> 328.47222 | T36: =(R36-P36)*86000/60 -> 39.814815 | V36: 45661.776 | W36: =V36+TIME(0,153,0) -> 45661.883 | X36: =(W36-V36)*84600/60 -> 149.8125 | Z36: 45662.614 | AA36: =Z36+TIME(0,57,0) -> 45662.653 | AB36: =(AA36-Z36)*84600/60 -> 55.8125 | AD36: =Z36-R36 -> 1.0305556 | AE36: 2 | AF36: =AE36-AD36 -> 0.96944444 | AG36: =AD36*24 -> 24.733333 | AH36: =AG36-AI36 -> 12 | AI36: =((Z36 - R36) * 24) - (INT(Z36 - R36) * 12) -> 12.733333 | AJ36: =I36/AI36 -> 12.062827
A37: 45660.986 | B37: =TEXT(A37, "MMMM") -> January | D37: OM4CG3KRR | E37: Manual | F37: Luyaga Isaac | G37: UAY 265V | H37: KATO INVESTMENTS LTD- KALISIZO | I37: 152.002 | J37: F15669 | K37: OM | L37: 350 | M37: 351 | N37: =M37-L37 -> 1 | P37: =R37-TIME(0,39,0) -> 45661.472 | Q37: 45661.354 | R37: 45661.499 | S37: =(R37-Q37)*86000/60 -> 208.03241 | T37: =(R37-P37)*86000/60 -> 38.819444 | V37: 45661.806 | W37: =V37+TIME(0,153,0) -> 45661.912 | X37: =(W37-V37)*84600/60 -> 149.8125 | Z37: 45662.757 | AA37: 45662.79 | AB37: =(AA37-Z37)*84600/60 -> 46.020833 | AD37: =Z37-R37 -> 1.2576389 | AE37: 2 | AF37: =AE37-AD37 -> 0.74236111 | AG37: =AD37*24 -> 30.183333 | AH37: =AG37-AI37 -> 12 | AI37: =((Z37 - R37) * 24) - (INT(Z37 - R37) * 12) -> 18.183333 | AJ37: =I37/AI37 -> 8.3594134
A38: 45661 | B38: =TEXT(A38, "MMMM") -> January | D38: OM02L7HP | E38: Manual | F38: MUKOSE MUZAMIRU | G38: UBE 690K | H38: Rugoma Traders-Rukungiri | I38: 156 | J38: Z82057 | K38: OM | L38: 256 | M38: =L38-1 -> 255 | N38: =M38-L38 -> -1 | P38: 45661.332 | Q38: 45661.312 | R38: 45661.36 | S38: =(R38-Q38)*86000/60 -> 67.685185 | T38: =(R38-P38)*86000/60 -> 39.814815 | V38: 45661.651 | W38: =V38+TIME(0,153,0) -> 45661.758 | X38: =(W38-V38)*84600/60 -> 149.8125 | Z38: 45661.876 | AA38: 45661.912 | AB38: =(AA38-Z38)*84600/60 -> 50.916667 | AD38: =Z38-R38 -> 0.51666667 | AE38: 2 | AF38: =AE38-AD38 -> 1.4833333 | AG38: =AD38*24 -> 12.4 | AH38: =AG38-AI38 -> 0 | AI38: =((Z38 - R38) * 24) - (INT(Z38 - R38) * 12) -> 12.4 | AJ38: =I38/AI38 -> 12.580645
A39: 45661 | B39: =TEXT(A39, "MMMM") -> January | D39: OM02L7EK | E39: Manual | F39: MUKOSE MUZAMIRU | G39: UBE 690K | H39: Kato Investment Ltd -Kagadi | I39: 156 | J39: A19840 | K39: OM | L39: 670 | M39: 612 | N39: =M39-L39 -> -58 | P39: =R39-TIME(0,44,0) -> 45661.306 | Q39: 45661.312 | R39: 45661.336 | S39: =(R39-Q39)*86000/60 -> 33.842593 | T39: =(R39-P39)*86000/60 -> 43.796296 | V39: 45662.482 | W39: =V39+TIME(0,175,0) -> 45662.603 | X39: =(W39-V39)*84600/60 -> 171.35417 | Z39: 45663.625 | AA39: =Z39+TIME(0,59,0) -> 45663.666 | AB39: =(AA39-Z39)*84600/60 -> 57.770833 | AD39: =Z39-R39 -> 2.2885556 | AE39: 2 | AF39: =AE39-AD39 -> -0.28855556 | AG39: =AD39*24 -> 54.925333 | AH39: =AG39-AI39 -> 24 | AI39: =((Z39 - R39) * 24) - (INT(Z39 - R39) * 12) -> 30.925333 | AJ39: =I39/AI39 -> 5.044408
A40: 45661 | B40: =TEXT(A40, "MMMM") -> January | D40: OM02L7EN | E40: Manual | G40: UBE 678K | H40: Ntale and Sons Ltd-Kakiri | I40: 156 | J40: A19842 | K40: OM | L40: 620 | M40: 602 | N40: =M40-L40 -> -18 | P40: =R40-TIME(0,44,0) -> 45661.329 | Q40: 45661.312 | R40: 45661.36 | S40: =(R40-Q40)*86000/60 -> 67.685185 | T40: =(R40-P40)*86000/60 -> 43.796296 | V40: 45661.881 | W40: =V40+TIME(0,153,0) -> 45661.987 | X40: =(W40-V40)*84600/60 -> 149.8125 | Z40: 45663.466 | AA40: 45663.5 | AB40: =(AA40-Z40)*84600/60 -> 47.979167 | AD40: =Z40-R40 -> 2.1058333 | AE40: 3 | AF40: =AE40-AD40 -> 0.89416667 | AG40: =AD40*24 -> 50.54 | AH40: =AG40-AI40 -> 24 | AI40: =((Z40 - R40) * 24) - (INT(Z40 - R40) * 12) -> 26.54 | AJ40: =I40/AI40 -> 5.8779201
...

Sheet Customer Master Data
A1: Customer Name | B1: Customer # | C1: Customer Name2 | D1: Customer Type | E1: Customer Contact Name | F1: Contact Role | G1: Contact Number 1 | H1: Contact no 2 | I1: Contact no 3 | J1: E-mail Adress | K1: Street | L1: Geography | M1: Latitude | N1: Latitude3 | O1: Call Type | P1: Call Frequency 1 | Q1: # DD | R1: Mon | S1: Tue | T1: Wed | U1: Thu | V1: Fri | W1: Sat | X1: Sun | Y1: Max Truck Capacity | Z1: Time Window | AA1: CIC Agent | AB1: Sales Rep / Distributor Specialist | AC1: Delivery Points | AD1: Max Stock Capacity at outlet cases | AE1: 12 month sales volume HL | AF1: 12 months # of deliveries | AG1: 12 Month # of FBR's | AH1: Credit Limit | AI1: Mon4 | AJ1: Tue5 | AK1: Wed6 | AL1: Thu7 | AM1: Fri8 | AN1: Sat9 | AO1: Sun10 | AP1: DEL DAYS COMBINED | AQ1: Budgeted KMs | AR1: Budget Cases | AS1: Lane allocation | AT1: Rate | AU1: Budget cost | AV1: Budget Net Revenue | AW1: Capacity Occupation | AX1: Budget: Cases /km | AY1: Cost/case UGX | AZ1: Net Revenue% Contribution | BA1: Cost/case Rank | BB1: Volume Contribution | BC1: Location type | BD1: Main catergory | BE1: Distribution Segmentation | BF1: Clustering | BG1: Volume % | BH1: NetReve Growth | BI1: Cost to deliver | BJ1: CO HL | BK1: OTIF | BL1: NPS | BM1: RMD | BN1: Points
A2: AGABA SERVICES | B2: BAGA011 | C2: BYARUGABA MOSES | D2: Distribution Centre | E2: BYARUGABA MOSES | F2: OWNER | G2: 777664482 | H2: 777664482 | I2: 777664482 | J2: kalvomark@yahoo.com | K2: KABALE | L2: KABALE | M2: -1.2994117 | N2: 29.998562 | O2: T | P2: Mon-Sun | Q2: 7 | R2: X | S2: X | T2: X | U2: X | V2: X | W2: X | X2: X | Y2: 20 | Z2: 0800-1700 | AA2: Samuel Kenneth Ssekajja | AB2: Samuel Kenneth Ssekajja | AC2: 1 | AD2: 50000 | AE2: 43087 | AF2: 298 | AG2: 0 | AH2: 1904117805 | AI2: Mon | AJ2: Tue | AK2: Wed | AL2: Thu | AM2: Fri | AN2: Sat | AO2: Sun | AP2: Mon Tue Wed Thu Fri Sat Sun | AQ2: 302 | AR2: 402290 | AS2: Own | AT2: 5349 | AU2: 293057907 | AV2: 12619053999 | AW2: 145 | AX2: 4 | AY2: 728 | AZ2: 0.05 | BA2: 7 | BB2: 0.047 | BC2: Semi Urban | BD2: Value | BE2: Semi Urban Value | BF2: Winner | BG2: 3 | BH2: 3 | BI2: 4 | BJ2: 4 | BK2: 0.0019 | BL2: 92 | BM2: 5 | BN2: 3.5
A3: BATES BUNDIBUGYO | B3: BBAT035 | C3: TIMOTHY BAGUMA | D3: Distributor CENTER | E3: TIMOTHY BAGUMA | F3: OWNER | G3: 772394539 | H3: 772394539 | I3: 772394539 | J3: batesenterprises@gmail.com | K3: BUNDIBUGYO | L3: BUNDIBUGYO | M3: 0.71131167 | N3: 30.062473 | O3: T | P3: Mon-Sun | Q3: 7 | R3: X | S3: X | T3: X | U3: X | V3: X | W3: X | X3: X | Y3: 20 | Z3: 0800-1700 | AA3: Steven R. Bazungu | AB3: Steven R. Bazungu | AC3: 1 | AD3: 12000 | AE3: 9258 | AF3: 65 | AG3: 0 | AH3: 0 | AI3: Mon | AJ3: Tue | AK3: Wed | AL3: Thu | AM3: Fri | AN3: Sat | AO3: Sun | AP3: Mon Tue Wed Thu Fri Sat Sun | AQ3: 464 | AR3: 87324 | AS3: 3PL | AT3: 7000 | AU3: 200132831 | AV3: 2769003228 | AW3: 143.1 | AX3: 3 | AY3: 2292 | AZ3: 0.01 | BA3: 16 | BB3: 0.01 | BC3: Rural | BD3: Core | BE3: Rural Core | BF3: Basic | BG3: 2 | BH3: 2 | BI3: 3 | BJ3: 3 | BK3: 0.0216 | BM3: 5 | BN3: 2.5
A4: BATES NTOROKO | B4: BBAT036 | C4: TIMOTHY BAGUMA | D4: Distributor CENTER | E4: TIMOTHY BAGUMA | F4: MANAGER | G4: 772394539 | H4: 772394539 | I4: 772394539 | J4: batesenterprises@gmail.com | K4: NTOROKO | L4: NTOROKO | M4: 0.91969842 | N4: 30.187996 | O4: T | P4: Mon-Sun | Q4: 7 | R4: X | S4: X | T4: X | U4: X | V4: X | W4: X | X4: X | Y4: 20 | Z4: 0800-1700 | AA4: Steven R. Bazungu | AB4: Steven R. Bazungu | AC4: 1 | AD4: 5000 | AE4: 10104 | AF4: 73 | AG4: 0 | AH4: 0 | AI4: Mon | AJ4: Tue | AK4: Wed | AL4: Thu | AM4: Fri | AN4: Sat | AO4: Sun | AP4: Mon Tue Wed Thu Fri Sat Sun | AQ4: 442 | AR4: 97944 | AS4: 3PL | AT4: 7000 | AU4: 235645554 | AV4: 3133122476 | AW4: 139 | AX4: 3 | AY4: 2406 | AZ4: 0.01 | BA4: 18 | BB4: 0.011 | BC4: Rural | BD4: Core | BE4: Rural Core | BF4: Basic | BG4: 2 | BH4: 2 | BI4: 3 | BJ4: 1 | BK4: 0.0002 | BM4: 5 | BN4: 2.17
A5: DE'PLACE INVESTMENT | B5: NDE 001 | C5: BINGI JULIUS | D5: Distribution Centre | E5: BINGI JULIUS | F5: OWNER | G5: 772220243 | H5: 772220243 | I5: 772220243 | J5: deplaceinvestmentltd@yahoo.com | K5: HOIMA | L5: HOIMA | M5: 1.426095 | N5: 31.348788 | O5: T | P5: Mon-Sun | Q5: 7 | R5: X | S5: X | T5: X | U5: X | V5: X | W5: X | X5: X | Y5: 20 | Z5: 0800-1700 | AA5: Gerald Mugisa | AB5: Steven R. Bazungu | AC5: 1 | AD5: 30000 | AE5: 50377 | AF5: 366 | AG5: 0 | AH5: 1757414453 | AI5: Mon | AJ5: Tue | AK5: Wed | AL5: Thu | AM5: Fri | AN5: Sat | AO5: Sun | AP5: Mon Tue Wed Thu Fri Sat Sun | AQ5: 314 | AR5: 494552 | AS5: 3PL | AT5: 6340 | AU5: 1463118903 | AV5: 15012580218 | AW5: 138 | AX5: 2 | AY5: 2958 | AZ5: 0.06 | BA5: 23 | BB5: 0.055 | BC5: Urban | BD5: Core | BE5: Urban Core | BF5: Low | BG5: 4 | BH5: 4 | BI5: 2 | BJ5: 1 | BK5: 0.0015 | BL5: -18 | BM5: 5 | BN5: -0.29
A6: HARERA KISORO | B6: NBON002 | C6: HARERA | D6: Distribution Centre | E6: HARERA | F6: MANAGER | G6: 392960091 | H6: 702454399 | I6: 702454399 | J6: hareraboniface@yahoo.com | K6: KISORO | L6: KISORO | M6: -1.2808083 | N6: 29.692868 | O6: T | P6: Mon-Sun | Q6: 7 | R6: X | S6: X | T6: X | U6: X | V6: X | W6: X | X6: X | Y6: 20 | Z6: 0800-1700 | AA6: Samuel Kenneth Ssekajja | AB6: Steven R. Bazungu | AC6: 1 | AD6: 20000 | AE6: 35603 | AF6: 255 | AG6: 0 | AH6: 1390823982 | AI6: Mon | AJ6: Tue | AK6: Wed | AL6: Thu | AM6: Fri | AN6: Sat | AO6: Sun | AP6: Mon Tue Wed Thu Fri Sat Sun | AQ6: 380 | AR6: 344088 | AS6: 3PL | AT6: 7000 | AU6: 799303852 | AV6: 10734224767 | AW6: 139.7 | AX6: 3 | AY6: 2323 | AZ6: 0.04 | BA6: 17 | BB6: 0.039 | BC6: Semi Urban | BD6: Value | BE6: Semi Urban Value | BF6: Winner | BG6: 3 | BH6: 3 | BI6: 3 | BJ6: 1 | BK6: 0.0049 | BL6: 96 | BM6: 5 | BN6: 15.86
A7: KABACO KASESE | B7: BKAB002 | C7: CHARITY TUSIIME | D7: Distribution Centre | E7: CHARITY TUSIIME | F7: MANAGER | G7: 772816012 | H7: 772816012 | I7: 772816012 | J7: kabacougltd@yahoo.com | K7: KASESE | L7: KASESE | M7: 0.17510333 | N7: 30.079502 | O7: T | P7: Mon-Sun | Q7: 7 | R7: X | S7: X | T7: X | U7: X | V7: X | W7: X | X7: X | Y7: 20 | Z7: 0800-1700 | AA7: Steven R. Bazungu | AB7: Steven R. Bazungu | AC7: 1 | AD7: 45000 | AE7: 46190 | AF7: 323 | AG7: 0 | AH7: 1719981262 | AI7: Mon | AJ7: Tue | AK7: Wed | AL7: Thu | AM7: Fri | AN7: Sat | AO7: Sun | AP7: Mon Tue Wed Thu Fri Sat Sun | AQ7: 298 | AR7: 436684 | AS7: 3PL | AT7: 7000 | AU7: 570600024 | AV7: 13573219881 | AW7: 143 | AX7: 5 | AY7: 1307 | AZ7: 0.05 | BA7: 10 | BB7: 0.051 | BC7: Semi Urban | BD7: Core | BE7: Semi Urban Core | BF7: Winner | BG7: 4 | BH7: 4 | BI7: 4 | BJ7: 2 | BK7: 0.0016 | BL7: 95 | BM7: 5 | BN7: 16.29
A8: KABACO MBARARA | B8: BKAB005 | C8: CHARITY TUSIIME | D8: Distribution Centre | E8: CHARITY TUSIIME | F8: MANAGER | G8: 772816012 | H8: 772816012 | I8: 772816012 | J8: kabacougltd@yahoo.com | K8: RUTI | L8: MBARARA | M8: -0.608141 | N8: 30.563436 | O8: T | P8: Mon-Sun | Q8: 7 | R8: X | S8: X | T8: X | U8: X | V8: X | W8: X | X8: X | Y8: 20 | Z8: 0800-1700 | AA8: Susan Twongyeirwe | AB8: Steven R. Bazungu | AC8: 1 | AD8: 50000 | AE8: 33232 | AF8: 240 | AG8: 0 | AH8: 1904117805 | AI8: Mon | AJ8: Tue | AK8: Wed | AL8: Thu | AM8: Fri | AN8: Sat | AO8: Sun | AP8: Mon Tue Wed Thu Fri Sat Sun | AQ8: 10 | AR8: 324252 | AS8: Own | AT8: 7000 | AU8: 15642972 | AV8: 10187466025 | AW8: 138 | AX8: 68 | AY8: 48 | AZ8: 0.04 | BA8: 2 | BB8: 0.036 | BC8: Semi Urban | BD8: Value | BE8: Semi Urban Value | BF8: Basic | BG8: 3 | BH8: 3 | BI8: 4 | BJ8: 1 | BK8: 0.0064 | BM8: 5 | BN8: 2.67
A9: KATO INVESTMENT BULENGA | B9: KKAT010 | C9: MATOVU FAHAD | D9: Distribution Centre | E9: MATOVU FAHAD | F9: MANAGER | G9: 777358546 | H9: 777358546 | I9: 777358546 | J9: Katoinvestmentslimited@yahoo.com | K9: BULENGA | L9: BULENGA | M9: 0.32629667 | N9: 32.500112 | O9: T | P9: Mon-Sun | Q9: 7 | R9: X | S9: X | T9: X | U9: X | V9: X | W9: X | X9: X | Y9: 20 | Z9: 0800-1700 | AA9: Ronald Kasumba | AB9: Ronald Kasumba | AC9: 1 | AD9: 15000 | AE9: 23251 | AF9: 169 | AG9: 0 | AH9: 1366003205 | AI9: Mon | AJ9: Tue | AK9: Wed | AL9: Thu | AM9: Fri | AN9: Sat | AO9: Sun | AP9: Mon Tue Wed Thu Fri Sat Sun | AQ9: 930 | AR9: 228238 | AS9: 3PL | AT9: 6447 | AU9: 610400408 | AV9: 7055644094 | AW9: 138 | AX9: 2 | AY9: 2674 | AZ9: 0.03 | BA9: 20 | BB9: 0.025 | BC9: Urban | BD9: Core | BE9: Urban Core | BF9: Winner | BG9: 2 | BH9: 2 | BI9: 2 | BJ9: 1 | BK9: 0.0008 | BL9: 40 | BM9: 5 | BN9: 7.43
A10: KATO INVESTMENT KAGADI | B10: KKAT003 | C10: Nasuna Florence | D10: Distributor CENTER | E10: Nasuna Florence | F10: MANAGER | G10: 782593227 | H10: 781472462 | I10: 781472462 | J10: Katoinvestmentslimited@yahoo.com | K10: KAGADI | L10: KAGADI | M10: 0.93529333 | N10: 30.814132 | O10: T | P10: Mon-Sun | Q10: 7 | R10: X | S10: X | T10: X | U10: X | V10: X | W10: X | X10: X | Y10: 20 | Z10: 0800-1700 | AA10: Ronald Kasumba | AB10: Ronald Kasumba | AC10: 1 | AD10: 20000 | AE10: 25392 | AF10: 184 | AG10: 0 | AH10: 916794238 | AI10: Mon | AJ10: Tue | AK10: Wed | AL10: Thu | AM10: Fri | AN10: Sat | AO10: Sun | AP10: Mon Tue Wed Thu Fri Sat Sun | AQ10: 298 | AR10: 248231 | AS10: 3PL | AT10: 6922 | AU10: 852723846 | AV10: 7048800085 | AW10: 138 | AX10: 2 | AY10: 3435 | AZ10: 0.03 | BA10: 26 | BB10: 0.028 | BC10: Rural | BD10: Value | BE10: Rural Value | BF10: Low | BG10: 2 | BH10: 2 | BI10: 1 | BJ10: 1 | BK10: 0.0009 | BL10: -1 | BM10: 5 | BN10: 1.43
A11: KATO INVESTMENT KAKUMIRO | B11: KKAT013 | C11: NANSUBUGA LUCIE | D11: Distribution Centre | E11: NANSUBUGA LUCIE | F11: MANAGER | G11: 782666861 | H11: 782666861 | I11: 782666861 | J11: Katoinvestmentslimited@yahoo.com | K11: KAKUMIRO | L11: KAKUMIRO | M11: 0.77657167 | N11: 31.323683 | O11: T | P11: Mon-Sun | Q11: 7 | R11: X | S11: X | T11: X | U11: x | V11: X | W11: x | X11: X | Y11: 20 | Z11: 0800-1700 | AA11: Ronald Kasumba | AB11: Ronald Kasumba | AC11: 1 | AD11: 15000 | AE11: 16097 | AF11: 113 | AG11: 0 | AH11: 570240618 | AI11: Mon | AJ11: Tue | AK11: Wed | AL11: Thu | AM11: Fri | AN11: Sat | AO11: Sun | AP11: Mon Tue Wed Thu Fri Sat Sun | AQ11: 304 | AR11: 153035 | AS11: 3PL | AT11: 5794 | AU11: 610822594 | AV11: 4654532750 | AW11: 142 | AX11: 1 | AY11: 3991 | AZ11: 0.02 | BA11: 28 | BB11: 0.018 | BC11: Rural | BD11: Value | BE11: Rural Value | BF11: Low | BG11: 2 | BH11: 2 | BI11: 1 | BJ11: 2 | BK11: 0.0006 | BL11: -56 | BM11: 5 | BN11: -6.29
A12: KATO INVESTMENT KALISIZO | B12: NKAT002 | C12: SIMON MAKODI | D12: Distribution Centre | E12: SIMON MAKODI | F12: MANAGER | G12: 777014145 | H12: 777014145 | I12: 777014145 | J12: Katoinvestmentslimited@yahoo.com | K12: KALISIZO | L12: KALISIZO | M12: -0.63392167 | N12: 31.542553 | O12: T | P12: Mon-Sun | Q12: 7 | R12: X | S12: X | T12: X | U12: X | V12: X | W12: X | X12: X | Y12: 20 | Z12: 0800-1700 | AA12: Susan Twongyeirwe | AB12: Susan Twongyeirwe | AC12: 1 | AD12: 27000 | AE12: 27641 | AF12: 214 | AG12: 0 | AH12: 1283853109 | AI12: Mon | AJ12: Tue | AK12: Wed | AL12: Thu | AM12: Fri | AN12: Sat | AO12: Sun | AP12: Mon Tue Wed Thu Fri Sat Sun | AQ12: 304 | AR12: 288577 | AS12: Own | AT12: - | AU12: 264515713 | AV12: 8388054767 | AW12: 129 | AX12: 4 | AY12: 917 | AZ12: 0.03 | BA12: 8 | BB12: 0.03 | BC12: Rural | BD12: Value | BE12: Rural Value | BF12: Basic | BG12: 3 | BH12: 3 | BI12: 4 | BJ12: 1 | BK12: 0.0016 | BM12: 5 | BN12: 2.67
A13: KATO INVESTMENT KATIKARA | B13: KKAT012 | C13: LUUTU JOSEPH | D13: Distribution Centre | E13: LUUTU JOSEPH | F13: MANAGER | G13: 787597266 | H13: 787597266 | I13: 787597266 | J13: Katoinvestmentslimited@yahoo.com | K13: KATIKARA | L13: KATIKARA | M13: 1.1480783 | N13: 31.284513 | O13: T | P13: Mon-Sun | Q13: 7 | R13: X | S13: X | T13: X | U13: X | V13: X | W13: X | X13: X | Y13: 20 | Z13: 0800-1700 | AA13: Ronald Kasumba | AB13: Ronald Kasumba | AC13: 1 | AD13: 20000 | AE13: 19321 | AF13: 135 | AG13: 0 | AH13: 749085617 | AI13: Mon | AJ13: Tue | AK13: Wed | AL13: Thu | AM13: Fri | AN13: Sat | AO13: Sun | AP13: Mon Tue Wed Thu Fri Sat Sun | AQ13: 252 | AR13: 181696 | AS13: 3PL | AT13: 7220 | AU13: 1010620741 | AV13: 5385847389 | AW13: 144 | AX13: 1 | AY13: 5562 | AZ13: 0.02 | BA13: 29 | BB13: 0.021 | BC13: Rural | BD13: Value | BE13: Rural Value | BF13: Low | BG13: 2 | BH13: 2 | BI13: 1 | BJ13: 3 | BK13: 0.001 | BL13: -27 | BM13: 5 | BN13: -2
A14: KATO INVESTMENT KYEGEGWA | B14: KKAT014 | C14: Ssemanda Herny | D14: Distributor CENTER | E14: Ssemanda Herny | F14: MANAGER | G14: 782685446 | H14: 782685446 | I14: 782685446 | J14: Katoinvestmentslimited@yahoo.com | K14: KYEGEGWA | L14: KYEGEGWA | M14: -0.480446 | N14: 31.057648 | O14: T | P14: Mon-Sun | Q14: 7 | R14: X | S14: X | T14: X | U14: X | V14: X | W14: X | X14: X | Y14: 20 | Z14: 0800-1700 | AA14: Ronald Kasumba | AB14: Ronald Kasumba | AC14: 1 | AD14: 8000 | AE14: 23684 | AF14: 180 | AG14: 0 | AH14: - | AI14: Mon | AJ14: Tue | AK14: Wed | AL14: Thu | AM14: Fri | AN14: Sat | AO14: Sun | AP14: Mon Tue Wed Thu Fri Sat Sun | AQ14: 630 | AR14: 242480 | AS14: 3PL | AT14: 5504 | AU14: 593115869 | AV14: 6520469909 | AW14: 132 | AX14: 2 | AY14: 2446 | AZ14: 0.02 | BA14: 19 | BB14: 0.026 | BC14: Rural | BD14: Value | BE14: Rural Value | BF14: Winner | BG14: 2 | BH14: 2 | BI14: 3 | BJ14: 1 | BK14: 0.0004 | BL14: 100 | BM14: 5 | BN14: 16.14
A15: KATO INVESTMENT MASAKA | B15: NKAT001 | C15: SIMON MAKODI | D15: Distribution Centre | E15: SIMON MAKODI | F15: MANAGER | G15: 777014145 | H15: 777014145 | I15: 777014145 | J15: Katoinvestmentslimited@yahoo.com | K15: MASAKA | L15: MASAKA | M15: -0.34422333 | N15: 31.739208 | O15: T | P15: Mon-Sun | Q15: 7 | R15: X | S15: X | T15: x | U15: X | V15: X | W15: X | X15: X | Y15: 20 | Z15: 0800-1700 | AA15: Susan Twongyeirwe | AB15: Susan Twongyeirwe | AC15: 1 | AD15: 35000 | AE15: 64058 | AF15: 459 | AG15: 0 | AH15: 2237641608 | AI15: Mon | AJ15: Tue | AK15: Wed | AL15: Thu | AM15: Fri | AN15: Sat | AO15: Sun | AP15: Mon Tue Wed Thu Fri Sat Sun | AQ15: 560 | AR15: 620159 | AS15: Own | AT15: 7000 | AU15: 445785551 | AV15: 19598862486 | AW15: 139 | AX15: 5 | AY15: 719 | AZ15: 0.07 | BA15: 6 | BB15: 0.07 | BC15: Urban | BD15: Core | BE15: Urban Core | BF15: Winner | BG15: 4 | BH15: 4 | BI15: 4 | BJ15: 1 | BK15: 0.0015 | BL15: 88 | BM15: 5 | BN15: 15.14
A16: KATO INVESTMENT MASAKA - SEMBABULE | B16: NKAT001 | C16: SIMON MAKODI | D16: Distribution Centre | E16: SIMON MAKODI | F16: MANAGER | G16: 777014145 | H16: 777014145 | I16: 777014145 | J16: Katoinvestmentslimited@yahoo.com | K16: MASAKA | L16: MASAKA | M16: -0.0819461 | N16: 31.458185 | O16: T | P16: Mon-Sun | Q16: 7 | R16: X | S16: X | T16: x | U16: X | V16: X | W16: X | X16: X | Y16: 20 | Z16: 0800-1700 | AA16: Susan Twongyeirwe | AB16: Susan Twongyeirwe | AC16: 1 | AF16: - | AG16: 0 | AH16: 2237641608 | AI16: Mon | AJ16: Tue | AK16: Wed | AL16: Thu | AM16: Fri | AN16: Sat | AO16: Sun | AP16: Mon Tue Wed Thu Fri Sat Sun | AQ16: 448 | AS16: Own | AT16: 7000 | AU16: - | BC16: Rural | BD16: Value | BE16: Rural Value | BF16: Winner | BM16: 5 | BN16: 5
A17: KATO INVESTMENT MIT - BUKUYA | B17: KKAT006 | C17: MUTUMBA ALLOYZIOUS | D17: Distribution Centre | E17: MUTUMBA ALLOYZIOUS | F17: MANAGER | G17: 789446768 | H17: 789446768 | I17: 789446768 | J17: Katoinvestmentslimited@yahoo.com | K17: BUKUYA | L17: BUKUYA | M17: 0.6743816 | N17: 31.836002 | O17: T | P17: Mon-Sun | Q17: 7 | R17: X | S17: X | T17: X | U17: X | V17: X | W17: X | X17: X | Y17: 20 | Z17: 0800-1700 | AA17: Ronald Kasumba | AB17: Ronald Kasumba | AC17: 1 | AF17: - | AG17: 0 | AH17: 1976369683 | AI17: Mon | AJ17: Tue | AK17: Wed | AL17: Thu | AM17: Fri | AN17: Sat | AO17: Sun | AP17: Mon Tue Wed Thu Fri Sat Sun | AQ17: 448 | AS17: 3PL | AT17: 6702 | AU17: - | BC17: Rural | BD17: Value | BE17: Rural Value | BF17: Winner | BM17: 5 | BN17: 5
